Workbook

Sheet INDICADORES UPAS
A2: UPA DE LUZIÂNIA - UPA II
C3: MARÇO.26 | D3: ABRIL.26 | E3: MAIO.26 | F3: JUNHO.26 | G3: JULHO.26 | H3: AGOSTO.26 | I3: SETEMBRO.26 | J3: OUTUBRO.26 | K3: NOVEMBRO.26 | L3: DEZEMBRO.26 | M3: JANEIRO.27 | N3: FEVEREIRO.27 | O3: TOTAL
A4: PACIENTES RECEPCIONADOS | C4: 8880 | D4: 12340 | E4: 5400 | O4: =SUM(C4:N4) -> 26620
A5: MÉDIA DIÁRIA | C5: =C4/31 -> 286.45161 | D5: =D4/30 -> 411.33333 | E5: =E4/31 -> 174.19355 | F5: =F4/30 -> 0 | G5: =G4/31 -> 0 | H5: =H4/31 -> 0 | I5: =I4/30 -> 0 | J5: =J4/31 -> 0 | K5: =K4/30 -> 0 | L5: =L4/31 -> 0 | M5: =M4/31 -> 0 | N5: =N4/28 -> 0 | O5: =AVERAGE(C5:N5) -> 72.664875
C7: MARÇO.26 | D7: ABRIL.26 | E7: MAIO.26 | F7: JUNHO.26 | G7: JULHO.26 | H7: AGOSTO.26 | I7: SETEMBRO.26 | J7: OUTUBRO.26 | K7: NOVEMBRO.26 | L7: DEZEMBRO.26 | M7: JANEIRO.27 | N7: FEVEREIRO.27 | O7: TOTAL
A8: ATENDIMENTOS MÉDICOS | C8: 12000 | D8: 9400 | E8: 10500 | F8: 12800 | O8: =SUM(C8:N8) -> 44700
A9: META | C9: 8000 | D9: 8000 | E9: 8000 | F9: 8000 | G9: 8000 | H9: 8000 | I9: 8000 | J9: 8000 | K9: 8000 | L9: 8000 | M9: 8000 | N9: 8000 | O9: =SUM(C9:N9) -> 96000
C11: MARÇO.26 | D11: ABRIL.26 | E11: MAIO.26 | F11: JUNHO.26 | G11: JULHO.26 | H11: AGOSTO.26 | I11: SETEMBRO.26 | J11: OUTUBRO.26 | K11: NOVEMBRO.26 | L11: DEZEMBRO.26 | M11: JANEIRO.27 | N11: FEVEREIRO.27 | O11: TOTAL
A12: ATENDIMENTOS POR CLASSIFICAÇÃO DE RISCO | B12: NÃO URGENTE (AZUL) | C12: 300 | D12: 34 | E12: 150 | O12: =SUM(C12:N12) -> 484
B13: POUCO URGENTE (VERDE) | C13: 96 | D13: 1240 | E13: 7580 | O13: =SUM(C13:N13) -> 8916
B14: URGENTE (AMARELO) | C14: 84 | D14: 1000 | E14: 3400 | O14: =SUM(C14:N14) -> 4484
B15: MUITO URGENTE (LARANJA) | C15: 16 | D15: 800 | E15: 200 | O15: =SUM(C15:N15) -> 1016
B16: EMERGÊNCIA (VERMELHO) | C16: 25 | D16: 59 | E16: 94 | O16: =SUM(C16:N16) -> 178
B17: Não informado | C17: 31 | D17: 21 | E17: 23 | O17: =SUM(C17:N17) -> 75
B18: TOTAL DE ATENDIMENTOS POR CLASSIFICAÇÃO DE RISCO | C18: =SUM(C12:C17) -> 552 | D18: =SUM(D12:D17) -> 3154 | E18: =SUM(E12:E17) -> 11447 | F18: =SUM(F12:F17) -> 0 | G18: =SUM(G12:G17) -> 0 | H18: =SUM(H12:H17) -> 0 | I18: =SUM(I12:I17) -> 0 | J18: =SUM(J12:J17) -> 0 | ... N18: =SUM(N12:N17) -> 0 | O18: =SUM(C18:N18) -> 15153
A20: PERCENTUAL DE ATENDIMENTOS POR CLASSIFICAÇÃO DE RISCOS | B20: NÃO URGENTE (AZUL) | C20: =C12/C18 -> 0.54347826 | D20: =D12/D18 -> 0.010779962 | E20: =E12/E18 -> 0.01310387 | F20: =F12/F18 -> #DIV/0! | G20: =G12/G18 -> #DIV/0! | H20: =H12/H18 -> #DIV/0! | I20: =I12/I18 -> #DIV/0! | J20: =J12/J18 -> #DIV/0! | ... N20: =N12/N18 -> #DIV/0! | O20: =AVERAGE(C20:N20) -> #DIV/0!
B21: POUCO URGENTE (VERDE) | C21: =C13/C18 -> 0.17391304 | D21: =D13/D18 -> 0.39315155 | E21: =E13/E18 -> 0.66218223 | F21: =F13/F18 -> #DIV/0! | G21: =G13/G18 -> #DIV/0! | H21: =H13/H18 -> #DIV/0! | I21: =I13/I18 -> #DIV/0! | J21: =J13/J18 -> #DIV/0! | ... N21: =N13/N18 -> #DIV/0! | O21: =AVERAGE(C21:N21) -> #DIV/0!
B22: URGENTE (AMARELO) | C22: =C14/C18 -> 0.15217391 | D22: =D14/D18 -> 0.3170577 | E22: =E14/E18 -> 0.29702105 | F22: =F14/F18 -> #DIV/0! | G22: =G14/G18 -> #DIV/0! | H22: =H14/H18 -> #DIV/0! | I22: =I14/I18 -> #DIV/0! | J22: =J14/J18 -> #DIV/0! | ... N22: =N14/N18 -> #DIV/0! | O22: =AVERAGE(C22:N22) -> #DIV/0!
B23: MUITO URGENTE (LARANJA) | C23: =C15/C18 -> 0.028985507 | D23: =D15/D18 -> 0.25364616 | E23: =E15/E18 -> 0.017471827 | F23: =F15/F18 -> #DIV/0! | G23: =G15/G18 -> #DIV/0! | H23: =H15/H18 -> #DIV/0! | I23: =I15/I18 -> #DIV/0! | J23: =J15/J18 -> #DIV/0! | ... N23: =N15/N18 -> #DIV/0! | O23: =AVERAGE(C23:N23) -> #DIV/0!
B24: EMERGÊNCIA (VERMELHO) | C24: =C16/C18 -> 0.045289855 | D24: =D16/D18 -> 0.018706405 | E24: =E16/E18 -> 0.0082117585 | F24: =F16/F18 -> #DIV/0! | G24: =G16/G18 -> #DIV/0! | H24: =H16/H18 -> #DIV/0! | I24: =I16/I18 -> #DIV/0! | J24: =J16/J18 -> #DIV/0! | ... N24: =N16/N18 -> #DIV/0! | O24: =AVERAGE(C24:N24) -> #DIV/0!
B25: Não Informado | C25: =C17/C18 -> 0.05615942 | D25: =D17/D18 -> 0.0066582118 | E25: =E17/E18 -> 0.0020092601 | F25: =F17/F18 -> #DIV/0! | G25: =G17/G18 -> #DIV/0! | H25: =H17/H18 -> #DIV/0! | I25: =I17/I18 -> #DIV/0! | J25: =J17/J18 -> #DIV/0! | ... N25: =N17/N18 -> #DIV/0! | O25: =AVERAGE(C25:N25) -> #DIV/0!
C27: MARÇO.26 | D27: ABRIL.26 | E27: MAIO.26 | F27: JUNHO.26 | G27: JULHO.26 | H27: AGOSTO.26 | I27: SETEMBRO.26 | J27: OUTUBRO.26 | K27: NOVEMBRO.26 | L27: DEZEMBRO.26 | M27: JANEIRO.27 | N27: FEVEREIRO.27 | O27: TOTAL
A28: TEMPO DE ESPERA PARA CLASSIFICAÇÃO DE RISCO | B28: MÉDIA GERAL | C28: 0.00625 | D28: 0.0083333333 | E28: 0.0076388889 | O28: =AVERAGE(C28:N28) -> 0.0074074074
A29: META | C29: 0.0069444444 | D29: 0.0069444444 | E29: 0.0069444444 | F29: 0.0069444444 | G29: 0.0069444444 | H29: 0.0069444444 | I29: 0.0069444444 | J29: 0.0069444444 | K29: 0.0069444444 | L29: 0.0069444444 | M29: 0.0069444444 | N29: 0.0069444444
C31: MARÇO.26 | D31: ABRIL.26 | E31: MAIO.26 | F31: JUNHO.26 | G31: JULHO.26 | H31: AGOSTO.26 | I31: SETEMBRO.26 | J31: OUTUBRO.26 | K31: NOVEMBRO.26 | L31: DEZEMBRO.26 | M31: JANEIRO.27 | N31: FEVEREIRO.27 | O31: TOTAL
A32: TEMPO MÉDIO DE ESPERA DE ATENDIMENTO MÉDICO POR CLASSIFICAÇÃO DE RISCO | B32: MÉDIA GERAL | C32: 0.040972222 | D32: 0.013888889 | E32: 0.0090277778 | O32: =AVERAGE(C32:N32) -> 0.021296296
C34: MARÇO.26 | D34: ABRIL.26 | E34: MAIO.26 | F34: JUNHO.26 | G34: JULHO.26 | H34: AGOSTO.26 | I34: SETEMBRO.26 | J34: OUTUBRO.26 | K34: NOVEMBRO.26 | L34: DEZEMBRO.26 | M34: JANEIRO.27 | N34: FEVEREIRO.27 | O34: TOTAL
A35: TEMPO DE PERMANÊNCIA DE PACIENTES INTERNADOS | B35: TEMPO MÉDIO DE PERMANÊNCIA GERAL | C35: 1.2084722 | D35: 1.1854167 | E35: 0.95833333 | O35: =AVERAGE(C35:N35) -> 1.1174074
C37: MARÇO.26 | D37: ABRIL.26 | E37: MAIO.26 | F37: JUNHO.26 | G37: JULHO.26 | H37: AGOSTO.26 | I37: SETEMBRO.26 | J37: OUTUBRO.26 | K37: NOVEMBRO.26 | L37: DEZEMBRO.26 | M37: JANEIRO.27 | N37: FEVEREIRO.27 | O37: TOTAL
A38: TEMPO DE PERMANÊNCIA DE PACIENTES SEM INTERNAÇÃO | B38: TEMPO MÉDIO DE PERMANÊNCIA ATENDIMENTOS DE PORTA | C38: 0.065972222 | D38: 0.086111111 | E38: 0.12777778 | O38: =AVERAGE(C38:N38) -> 0.093287037
C40: MARÇO.26 | D40: ABRIL.26 | E40: MAIO.26 | F40: JUNHO.26 | G40: JULHO.26 | H40: AGOSTO.26 | I40: SETEMBRO.26 | J40: OUTUBRO.26 | K40: NOVEMBRO.26 | L40: DEZEMBRO.26 | M40: JANEIRO.27 | N40: FEVEREIRO.27 | O40: TOTAL
A41: TRANSFERÊNCIAS (REMOÇÕES) | B41: PERCENTUAL DE TRANSFERÊNCIAS PACIENTES INTERNADOS POR USA | C41: 64 | D41: 12 | E41: 23 | O41: =SUM(C41:N41) -> 99
C43: MARÇO.26 | D43: ABRIL.26 | E43: MAIO.26 | F43: JUNHO.26 | G43: JULHO.26 | H43: AGOSTO.26 | I43: SETEMBRO.26 | J43: OUTUBRO.26 | K43: NOVEMBRO.26 | L43: DEZEMBRO.26 | M43: JANEIRO.27 | N43: FEVEREIRO.27 | O43: TOTAL
A44: EXAMES INTERNOS | B44: RAIO-X | C44: 1200 | D44: 1350 | E44: 100 | O44: =SUM(C44:N44) -> 2650
B45: PATOLOGIA CLINICA | C45: 340 | D45: 845 | E45: 201 | O45: =SUM(C45:N45) -> 1386
B46: ELETROCARDIOGRAMA | C46: 152 | D46: 94 | E46: 90 | O46: =SUM(C46:N46) -> 336
B47: TOTAL | C47: =SUM(C44:C46) -> 1692 | D47: =SUM(D44:D46) -> 2289 | E47: =SUM(E44:E46) -> 391 | F47: =SUM(F44:F46) -> 0 | G47: =SUM(G44:G46) -> 0 | H47: =SUM(H44:H46) -> 0 | I47: =SUM(I44:I46) -> 0 | J47: =SUM(J44:J46) -> 0 | ... N47: =SUM(N44:N46) -> 0 | O47: =SUM(C47:N47) -> 4372
C49: MARÇO.26 | D49: ABRIL.26 | E49: MAIO.26 | F49: JUNHO.26 | G49: JULHO.26 | H49: AGOSTO.26 | I49: SETEMBRO.26 | J49: OUTUBRO.26 | K49: NOVEMBRO.26 | L49: DEZEMBRO.26 | M49: JANEIRO.27 | N49: FEVEREIRO.27 | O49: TOTAL
A50: ATENDIMENTOS DIVIDIDOS POR FAIXA ETARIA | B50: < 1 ANO | C50: 245 | D50: 2626 | E50: 312 | O50: =SUM(C50:N50) -> 3183
B51: 1 - 4 ANOS | C51: 84 | D51: 3434 | E51: 29 | O51: =SUM(C51:N51) -> 3547
...

Sheet DASHBORD UPAS

Sheet Planilha1
A1: Análise Quantitativa do Trimestre
A2: MÊS | B2: Pontuação Atingida | C2: Meta
A3: ABRIL | B3: 300 | C3: 241
A4: MAIO | B4: 285 | C4: 241
A5: JUNHO | B5: 300 | C5: 241
A10: Percentual de Desistência de Atendimento Médico | B10: 0.0055
A11: Meta | B11: 0.05
A24: Descrição | B24: Valor
A25: Consultas Realizadas no Trimestre | B25: 36699
A26: Meta Trimestral | B26: 24000
B30: ABRIL | C30: MAIO | D30: JUNHO
A31: Atendimento Assistência Social | B31: 378 | C31: 501 | D31: 445
B33: ABRIL | C33: MAIO | D33: JUNHO
A34: Quadro Geral | B34: 0.13125 | C34: 0.21074074 | D34: 0.13873843
A35: Meta | B35: 0.083333333 | C35: 0.083333333 | D35: 0.083333333
B38: ABRIL | C38: MAIO | D38: JUNHO
A39: Equipe Médica | B39: 0.88 | C39: 0.81 | D39: 0.96
A40: Meta | B40: 0.8 | C40: 0.8 | D40: 0.8
B42: ABRIL | C42: MAIO | D42: JUNHO
A43: Total de Notificações | B43: 455 | C43: 396 | D43: 320
A44: Percentual de Preenchimento Correto | B44: 1 | C44: 1 | D44: 1

Sheet 1.TRIMESTRE
A1: Item | B1: Meta | C1: Forma de avaliação / memória de cálculo | E1: JANEIRO | F1: FEVEREIRO | G1: MARÇO | H1: MÉDIA TRIMESTRAL
A2: 1 | B2: Taxa de satisfação do usuário | C2: Meta | D2: ≥ 80% | E2: ='INDICADORES UPAS'!#REF! -> #REF! | F2: ='INDICADORES UPAS'!#REF! -> #REF! | G2: ='INDICADORES UPAS'!#REF! -> #REF! | H2: =AVERAGE(E2:G2) -> #REF! | I2: Consultas Realizadas | J2: =SUM(E30:G30) -> 0 | T2: 0.083333333 | U2: 0.083333333 | V2: 0.083333333 | W2: 0.8 | X2: 0.8 | Y2: 0.8
C3: Pontuação | D3: 10 | E3: 10 | F3: 10 | G3: 10 | H3: =AVERAGE(E3:G3) -> 10 | I3: Meta Trimestral | J3: =8000*3 -> 24000
A4: 2 | B4: Taxa de usuários classificados como risco VERMELHO com tempo máximo de espera de 5 minutos para atendimento médico. | C4: Meta | D4: ≥ 95% | E4: ='INDICADORES UPAS'!#REF! -> #REF! | F4: ='INDICADORES UPAS'!#REF! -> #REF! | G4: ='INDICADORES UPAS'!#REF! -> #REF! | H4: =AVERAGE(E4:G4) -> #REF!
C5: Pontuação | D5: 20 | E5: 20 | F5: 20 | G5: 20 | H5: =AVERAGE(E5:G5) -> 20
A6: 3 | B6: Média no tempo de espera para atendimento médico no eixo VERMELHO | C6: Meta | D6: ≤ 5min | E6: ='INDICADORES UPAS'!#REF! -> #REF! | F6: ='INDICADORES UPAS'!#REF! -> #REF! | G6: ='INDICADORES UPAS'!#REF! -> #REF! | H6: =AVERAGE(E6:G6) -> #REF!
C7: Pontuação | D7: 20 | E7: 20 | F7: 20 | G7: 20 | H7: =AVERAGE(E7:G7) -> 20
A8: 4 | B8: Taxa de usuários classificados como risco LARANJA com tempo máximo de espera de 10 minutos para atendimento médico. | C8: Meta | D8: ≥ 85% | E8: ='INDICADORES UPAS'!#REF! -> #REF! | F8: ='INDICADORES UPAS'!#REF! -> #REF! | G8: ='INDICADORES UPAS'!#REF! -> #REF! | H8: =AVERAGE(E8:G8) -> #REF!
C9: Pontuação | D9: 20 | E9: 20 | F9: 20 | G9: 20 | H9: =AVERAGE(E9:G9) -> 20
A10: 5 | B10: Média no tempo de espera para atendimento médico no eixo LARANJA | C10: Meta | D10: ≤ 10min | E10: ='INDICADORES UPAS'!#REF! -> #REF! | F10: ='INDICADORES UPAS'!#REF! -> #REF! | G10: ='INDICADORES UPAS'!#REF! -> #REF! | H10: =AVERAGE(E10:G10) -> #REF!
C11: Pontuação | D11: 20 | E11: 20 | F11: 20 | G11: 20 | H11: =AVERAGE(E11:G11) -> 20
A12: 6 | B12: Taxa de usuários classificados como risco AMARELO com tempo máximo de espera de 60 minutos para atendimento médico. | C12: Meta | D12: ≥ 90% | E12: ='INDICADORES UPAS'!#REF! -> #REF! | F12: ='INDICADORES UPAS'!#REF! -> #REF! | G12: ='INDICADORES UPAS'!#REF! -> #REF! | H12: =AVERAGE(E12:G12) -> #REF!
C13: Pontuação | D13: 15 | E13: 15 | F13: 15 | G13: 15 | H13: =AVERAGE(E13:G13) -> 15
A14: 7 | B14: Média no tempo de espera para atendimento médico no eixo AMARELO | C14: Meta | D14: ≤ 60min | E14: ='INDICADORES UPAS'!#REF! -> #REF! | F14: ='INDICADORES UPAS'!#REF! -> #REF! | G14: ='INDICADORES UPAS'!#REF! -> #REF! | H14: =AVERAGE(E14:G14) -> #REF!
C15: Pontuação | D15: 15 | E15: 15 | F15: 15 | G15: 15 | H15: =AVERAGE(E15:G15) -> 15
A16: 8 | B16: Taxa de usuários classificados como risco VERDE com tempo máximo de espera de 120 minutos para atendimento médico. | C16: Meta | D16: ≥ 80% | E16: ='INDICADORES UPAS'!#REF! -> #REF! | F16: ='INDICADORES UPAS'!#REF! -> #REF! | G16: ='INDICADORES UPAS'!#REF! -> #REF! | H16: =AVERAGE(E16:G16) -> #REF!
C17: Pontuação | D17: 15 | E17: 15 | F17: 15 | G17: 15 | H17: =AVERAGE(E17:G17) -> 15
A18: 9 | B18: Média no tempo de espera para atendimento médico no eixo VERDE | C18: Meta | D18: ≤ 120min | E18: ='INDICADORES UPAS'!#REF! -> #REF! | F18: ='INDICADORES UPAS'!#REF! -> #REF! | G18: ='INDICADORES UPAS'!#REF! -> #REF! | H18: =AVERAGE(E18:G18) -> #REF!
C19: Pontuação | D19: 15 | E19: 15 | F19: 15 | G19: 15 | H19: =AVERAGE(E19:G19) -> 15
A20: 10 | B20: Taxa de usuários classificados como risco AZUL com tempo máximo de espera de 240 minutos para atendimento médico. | C20: Meta | D20: ≥ 80% | E20: ='INDICADORES UPAS'!#REF! -> #REF! | F20: ='INDICADORES UPAS'!#REF! -> #REF! | G20: ='INDICADORES UPAS'!#REF! -> #REF! | H20: =AVERAGE(E20:G20) -> #REF!
C21: Pontuação | D21: 10 | E21: 10 | F21: 10 | G21: 10 | H21: =AVERAGE(E21:G21) -> 10
A22: 11 | B22: Média no tempo de espera para atendimento médico no eixo AZUL | C22: Meta | D22: ≤ 240min | E22: ='INDICADORES UPAS'!#REF! -> #REF! | F22: ='INDICADORES UPAS'!#REF! -> #REF! | G22: ='INDICADORES UPAS'!#REF! -> #REF! | H22: =AVERAGE(E22:G22) -> #REF!
C23: Pontuação | D23: 10 | E23: 10 | F23: 10 | G23: 10 | H23: =AVERAGE(E23:G23) -> 10
A24: 12 | B24: Realizar 100% a Classificação de Risco dos pacientes que procuram atendimentos de urgência e emergência. | C24: Meta | D24: =100% -> 1 | E24: 1 | F24: 1 | G24: 1 | H24: =AVERAGE(E24:G24) -> 1
C25: Pontuação | D25: 15 | E25: 15 | F25: 15 | G25: 15 | H25: =AVERAGE(E25:G25) -> 15
A26: 13 | B26: Média no tempo de espera para Classificação de riscos | C26: Meta | D26: ≤ 10min | E26: ='INDICADORES UPAS'!I28 -> 0 | F26: ='INDICADORES UPAS'!J28 -> 0 | G26: ='INDICADORES UPAS'!K28 -> 0 | H26: =AVERAGE(E26:G26) -> 0
C27: Pontuação | D27: 15 | E27: 15 | F27: 15 | G27: 15 | H27: =AVERAGE(E27:G27) -> 15
A28: 14 | B28: Percentual de desistência de atendimento médico | C28: Meta | D28: ≤ 5% | E28: ='INDICADORES UPAS'!#REF! -> #REF! | F28: ='INDICADORES UPAS'!#REF! -> #REF! | G28: ='INDICADORES UPAS'!#REF! -> #REF! | H28: =AVERAGE(E28:G28) -> #REF! | I28: 0.05
C29: Pontuação | D29: 10 | E29: 10 | F29: 10 | G29: 10 | H29: =AVERAGE(E29:G29) -> 10
A30: 15 | B30: Número de Consultas Médicas mensais | C30: Meta | D30: ≥ 8.000 | E30: ='INDICADORES UPAS'!I8 -> 0 | F30: ='INDICADORES UPAS'!J8 -> 0 | G30: ='INDICADORES UPAS'!K8 -> 0 | H30: =AVERAGE(E30:G30) -> 0
C31: Pontuação | D31: 10 | E31: 10 | F31: 10 | G31: 10 | H31: =AVERAGE(E31:G31) -> 10
A32: 16 | B32: Registro em CLM ou CLP | C32: Meta | D32: 1 | E32: 1 | F32: 1 | G32: 1 | H32: =AVERAGE(E32:G32) -> 1
C33: Pontuação | D33: 5 | E33: 5 | F33: 5 | G33: 5 | H33: =AVERAGE(E33:G33) -> 5
A34: 17 | B34: Atendimento assistência social | C34: Meta | D34: 1 | E34: 1 | F34: 1 | G34: 1 | H34: =AVERAGE(E34:G34) -> 1
C35: Pontuação | D35: 10 | E35: 10 | F35: 10 | G35: 10 | H35: =AVERAGE(E35:G35) -> 10
A36: 18 | B36: Capacitação quadro geral | C36: Meta | D36: ≥ 2 horas | E36: ='INDICADORES UPAS'!#REF! -> #REF! | F36: ='INDICADORES UPAS'!#REF! -> #REF! | G36: ='INDICADORES UPAS'!#REF! -> #REF! | H36: =AVERAGE(E36:G36) -> #REF!
C37: Pontuação | D37: 5 | E37: 5 | F37: 5 | G37: 5 | H37: =AVERAGE(E37:G37) -> 5
A38: 19 | B38: Capacitação equipe médica | C38: Meta | D38: ≥80% | E38: ='INDICADORES UPAS'!#REF! -> #REF! | F38: ='INDICADORES UPAS'!#REF! -> #REF! | G38: ='INDICADORES UPAS'!#REF! -> #REF! | H38: =AVERAGE(E38:G38) -> #REF!
C39: Pontuação | D39: 5 | E39: 5 | F39: 5 | G39: 5 | H39: =AVERAGE(E39:G39) -> 5
A40: 20 | B40: Reuniões das comissões implantadas | C40: Meta | D40: 1 | E40: 1 | F40: 1 | G40: 1 | H40: =AVERAGE(E40:G40) -> 1
...

Sheet ATENDIMENTOS
A1: ATENDIMENTOS
A155: HORÁRIO | B155: QTD GERAL | C155: QTD DIA | D155: QTD HORA
A156: 00:00 às 02:59 | B156: 2623 | C156: =B156/184 -> 14.255435 | D156: =C156/3 -> 4.7518116
A157: 03:00 às 05:59 | B157: 2646 | C157: =B157/184 -> 14.380435 | D157: =C157/3 -> 4.7934783
A158: 06:00 às 08:59 | B158: 9979 | C158: =B158/184 -> 54.233696 | D158: =C158/3 -> 18.077899
A159: 09:00 às 11:59 | B159: 11226 | C159: =B159/184 -> 61.01087 | D159: =C159/3 -> 20.336957
A160: 12:00 às 14:59 | B160: 10679 | C160: =B160/184 -> 58.038043 | D160: =C160/3 -> 19.346014
A161: 15:00 às 17:59 | B161: 8740 | C161: =B161/184 -> 47.5 | D161: =C161/3 -> 15.833333
A162: 18:00 às 20:59 | B162: 9303 | C162: =B162/184 -> 50.559783 | D162: =C162/3 -> 16.853261
A163: 21:00 às 23:59 | B163: 6015 | C163: =B163/184 -> 32.690217 | D163: =C163/3 -> 10.896739
A164: TOTAIS | B164: =SUM(B156:B163) -> 61211 | C164: =B164/184 -> 332.66848 | D164: =C164/3 -> 110.88949

Sheet CONTROLE DIÁRIO DE ATENDIMENTOS
A1: Controle Diário de Atendimentos
A2: AGOSTO.2025
A3: SM | B3: DATA | C3: QTD | D3: T.EXCEDIDO | E3: % EFETIVIDADE | F3: META
A4: S | B4: 1 | C4: 349 | D4: 0 | E4: =(C4-D4)/C4 -> 1 | F4: 0.85
A5: S | B5: 2 | C5: 279 | D5: 0 | E5: =(C5-D5)/C5 -> 1 | F5: 0.85
A6: D | B6: 3 | C6: 291 | D6: 0 | E6: =(C6-D6)/C6 -> 1 | F6: 0.85
A7: S | B7: 4 | C7: 499 | D7: 0 | E7: =(C7-D7)/C7 -> 1 | F7: 0.85
A8: T | B8: 5 | C8: 374 | D8: 0 | E8: =(C8-D8)/C8 -> 1 | F8: 0.85
A9: Q | B9: 6 | C9: 381 | D9: 0 | E9: =(C9-D9)/C9 -> 1 | F9: 0.85
A10: Q | B10: 7 | C10: 443 | D10: 0 | E10: =(C10-D10)/C10 -> 1 | F10: 0.85
A11: S | B11: 8 | C11: 367 | D11: 0 | E11: =(C11-D11)/C11 -> 1 | F11: 0.85
A12: S | B12: 9 | C12: 273 | D12: 0 | E12: =(C12-D12)/C12 -> 1 | F12: 0.85
A13: D | B13: 10 | C13: 233 | D13: 0 | E13: =(C13-D13)/C13 -> 1 | F13: 0.85
A14: S | B14: 11 | C14: 508 | D14: 152 | E14: =(C14-D14)/C14 -> 0.7007874 | F14: 0.85
A15: T | B15: 12 | C15: 472 | D15: 11 | E15: =(C15-D15)/C15 -> 0.97669492 | F15: 0.85
... A25: S | B25: 22 | C25: 483 | D25: 64 | E25: =(C25-D25)/C25 -> 0.86749482 | F25: 0.85
A26: S | B26: 23 | C26: 370 | D26: 17 | E26: =(C26-D26)/C26 -> 0.95405405 | F26: 0.85 | T26: AGOSTO.2025
A27: D | B27: 24 | C27: 345 | D27: 0 | E27: =(C27-D27)/C27 -> 1 | F27: 0.85 | T27: SM | U27: Qtd | V27: Média
A28: S | B28: 25 | C28: 588 | D28: 177 | E28: =(C28-D28)/C28 -> 0.69897959 | F28: 0.85 | T28: Segunda | U28: =SUM(C7,C14,C21,C28) -> 2196 | V28: =AVERAGE(C7,C14,C21,C28) -> 549
A29: T | B29: 26 | C29: 476 | D29: 1 | E29: =(C29-D29)/C29 -> 0.99789916 | F29: 0.85 | T29: Terça | U29: =SUM(C8,C15,C22,C29) -> 1832 | V29: =AVERAGE(C8,C15,C22,C29) -> 458
A30: Q | B30: 27 | C30: 469 | D30: 4 | E30: =(C30-D30)/C30 -> 0.99147122 | F30: 0.85 | T30: Quarta | U30: =SUM(C9,C16,C23,C30) -> 1787 | V30: =AVERAGE(C9,C16,C23,C30) -> 446.75
A31: Q | B31: 28 | C31: 522 | D31: 43 | E31: =(C31-D31)/C31 -> 0.91762452 | F31: 0.85 | T31: Quinta | U31: =SUM(C10,C17,C24,C31) -> 1872 | V31: =AVERAGE(C10,C17,C24,C31) -> 468
A32: S | B32: 29 | C32: 466 | D32: 79 | E32: =(C32-D32)/C32 -> 0.8304721 | F32: 0.85 | T32: Sexta | U32: =SUM(C4,C11,C18,C25,C32) -> 2067 | V32: =AVERAGE(C4,C11,C18,C25,C32) -> 413.4
A33: S | B33: 30 | C33: 315 | D33: 0 | E33: =(C33-D33)/C33 -> 1 | F33: 0.85 | T33: Sábado | U33: =SUM(C5,C12,C19,C26,C33) -> 1569 | V33: =AVERAGE(C5,C12,C19,C26,C33) -> 313.8
A34: D | B34: 31 | C34: 335 | D34: 2 | E34: =(C34-D34)/C34 -> 0.99402985 | F34: 0.85 | T34: Domingo | U34: =SUM(C6,C13,C20,C27,C34) -> 1532 | V34: =AVERAGE(C6,C13,C20,C27,C34) -> 306.4
A35: Total | C35: =SUM(C4:C34) -> 12855 | D35: =SUM(D4:D34) -> 875 | E35: =AVERAGE(E4:E34) -> 0.94522222 | T35: Total | U35: =SUM(U28:U34) -> 12855 | V35: =AVERAGE(C4:C34) -> 414.67742
A38: SETEMBRO.2025
A39: SM | B39: DATA | C39: QTD | D39: T.EXCEDIDO | E39: % EFETIVIDADE | F39: META
A40: S | B40: 1 | C40: 553 | D40: 87 | E40: =(C40-D40)/C40 -> 0.84267631 | F40: 0.85
A41: T | B41: 2 | C41: 511 | D41: 68 | E41: =(C41-D41)/C41 -> 0.86692759 | F41: 0.85
A42: Q | B42: 3 | C42: 510 | D42: 15 | E42: =(C42-D42)/C42 -> 0.97058824 | F42: 0.85
A43: Q | B43: 4 | C43: 459 | D43: 0 | E43: =(C43-D43)/C43 -> 1 | F43: 0.85
A44: S | B44: 5 | C44: 431 | D44: 0 | E44: =(C44-D44)/C44 -> 1 | F44: 0.85
A45: S | B45: 6 | C45: 332 | D45: 0 | E45: =(C45-D45)/C45 -> 1 | F45: 0.85
A46: D | B46: 7 | C46: 288 | D46: 1 | E46: =(C46-D46)/C46 -> 0.99652778 | F46: 0.85
A47: S | B47: 8 | C47: 527 | D47: 133 | E47: =(C47-D47)/C47 -> 0.74762808 | F47: 0.85
A48: T | B48: 9 | C48: 514 | D48: 57 | E48: =(C48-D48)/C48 -> 0.88910506 | F48: 0.85
A49: Q | B49: 10 | C49: 490 | D49: 46 | E49: =(C49-D49)/C49 -> 0.90612245 | F49: 0.85
A50: Q | B50: 11 | C50: 486 | D50: 25 | E50: =(C50-D50)/C50 -> 0.94855967 | F50: 0.85
A51: S | B51: 12 | C51: 453 | D51: 25 | E51: =(C51-D51)/C51 -> 0.94481236 | F51: 0.85
...

Sheet INTERNAÇÕES
A1: INTERNAÇÕES
L23: HOSPITAL DE OLHOS DO PARANA | M23: 1
L24: HOSPITAL DE CLINICAS | M24: 1
L25: AMBULATORIO DO HOSPITAL EVANGELICO | M25: 1
L26: CRUZ VERMELHA | M26: 2
L27: HOSPITAL DE CLINICAS | M27: 2
L28: HOSPITAL NOSSA SENHORA DO ROCIO | M28: 2
L29: HEC HOSPITAL EVANGELICO DE CURITIBA | M29: 2
L30: HOSPITAL NOSSA SENHORA DA LUZ | M30: 2
L31: HOSPITAL INFANTIL PEQUENO PRINCIPE | M31: 3
L32: HOSPITAL ANGELINA CARON | M32: 6
L33: HOSPITAL E MATERNIDADE DE PINHAIS | M33: 7
L34: HMSJP - HOSPITAL MUNICIPAL SAO JOSE | M34: 8
... L38: HOSPITAL ANGELINA CARON | M38: 110

Sheet SADT
A1: SERVIÇO DE APOIO DIAGNÓSTICO TERAPÊUTICO
A63: EXAME | B63: QTD
A64: ULTRASSONOGRAFIA DE PARTES MOLES | B64: 1
A65: TOMOGRAFIA COMPUTADORIZADA DE PESCOÇO | B65: 1
A66: TOMOGRAFIA COMPUTADORIZADA DO TORAX | B66: 2
A67: TOMOGRAFIA DE ABDOMEN INFERIOR | B67: 6
A68: TOMOGRAFIA DE ABDOMEN SUPERIOR | B68: 7
A69: TOMOGRAFIA COMPUTADORIZADA DO CRANIO | B69: 18

Sheet CME
A1: CENTRAL DE MATERIAL ESTERILIZADO
A2: ESTERILIZAÇÃO | B2: QTD
A3: AUTOCLAVE | B3: 311
A4: QUÍMICO | B4: 2120
A5: TOTAL | B5: =SUM(B3:B4) -> 2431
A16: Material | B16: Setor | E16: Total Geral
B17: Emergência | C17: Medicação Rápida | D17: Observação
A18: BDJ ANESTESIA | B18: 1 | E18: 1
A19: CAIXA PARTO | B19: 2 | E19: 2
A20: PINÇA PEAN | B20: 4 | E20: 4
A21: CUBA 8 CM | B21: 6 | D21: 2 | E21: 8
A22: PINÇA KELLY RETA | B22: 7 | D22: 2 | E22: 9
A23: CX PEQ CIRURGIA | B23: 9 | E23: 9
A24: CAMPO FENESTRADO | B24: 8 | D24: 4 | E24: 12
A25: RETIRADA DE PONTOS | B25: 13 | E25: 13
A26: CIRCUITO | B26: 18 | E26: 18
A27: FIO GUIA | B27: 14 | D27: 5 | E27: 19
A28: CURATIVO | B28: 20 | E28: 20
A29: CAMPO CIRURGICO | B29: 20 | D29: 1 | E29: 21
A30: AVENTAL ESTERIL | B30: 19 | D30: 2 | E30: 21
A31: COMADRE | B31: 16 | C31: 4 | D31: 2 | E31: 22
A32: AMBU | B32: 23 | E32: 23
A33: CUBA RIM | B33: 21 | D33: 4 | E33: 25
A34: BACIA | B34: 27 | C34: 5 | D34: 23 | E34: 55
A35: CATETERISMO | B35: 27 | C35: 24 | D35: 11 | E35: 62
A36: FRASCO ASPIRAÇÃO | B36: 51 | D36: 12 | E36: 63
A37: MASCARA ALTO FLUXO | B37: 29 | C37: 37 | D37: 9 | E37: 75
A38: PAPAGAIO | B38: 53 | C38: 15 | D38: 34 | E38: 102
A39: SUTURA | B39: 111 | E39: 111
A40: LATEX | B40: 60 | C40: 72 | D40: 14 | E40: 146
A41: UMIDIFICADOR | B41: 58 | C41: 77 | D41: 13 | E41: 148
A42: NBZ | B42: 33 | C42: 290 | D42: 33 | E42: 356
A43: ESPAÇADOR | B43: 47 | C43: 326 | D43: 46 | E43: 419
A44: Total Geral | B44: =SUM(B18:B43) -> 697 | C44: =SUM(C18:C43) -> 850 | D44: =SUM(D18:D43) -> 217 | E44: =SUM(E18:E43) -> 1764
A45: Percentual | B45: =B44/E44 -> 0.39512472 | C45: =C44/E44 -> 0.48185941 | D45: =D44/E44 -> 0.12301587

Sheet NVE
A1: NÚCLEO DE VIGILÂNCIA EPIDEMIOLÓGICA
Y6: HEPATITE B | AA6: HEPATITE C | AC6: HIV
Y7: NÃO REAGENTES | Z7: 30 | AA7: NÃO REAGENTES | AB7: 31 | AC7: NÃO REAGENTES | AD7: 33
Y8: REAGENTES | Z8: 0 | AA8: REAGENTES | AB8: 0 | AC8: REAGENTES | AD8: 3
Y9: SÍFILIS | AA9: DENGUE | AC9: COVID
Y10: NÃO REAGENTES | Z10: 31 | AA10: NÃO REAGENTES | AB10: 15 | AC10: NÃO REAGENTES | AD10: 105
Y11: REAGENTES | Z11: 4 | AA11: REAGENTES | AB11: 1 | AC11: REAGENTES | AD11: 10
A42: Dezembro
A43: Notificação | B43: Qtd
A44: Coqueluche | B44: 1
A45: Meningete | B45: 1
A46: Doenças exantematicas | B46: 1
A47: AIDS | B47: 2
A48: Tuberculose | B48: 3
A49: Caxumba | B49: 3
A50: Esporotricose | B50: 4
A51: Dengue | B51: 5
A52: Sifilis | B52: 6
A53: Mão pé boca | B53: 7
A54: Animais peçonhentos | B54: 11
A55: COVID | B55: 12
... A62: Conjuntivite | B62: 71
A72: Total | B72: =SUM(B44:B71) -> 392
B94: JULHO | C94: AGOSTO | D94: SETEMBRO | E94: OUTUBRO.24 | F94: NOVEMBRO.24 | G94: DEZEMBRO.24 | H94: JANEIRO.25 | I94: FEVEREIRO.25 | J94: MARÇO.25 | K94: ABRIL.25 | L94: MAIO.25 | M94: JUNHO.25 | N94: JULHO.25 | O94: AGOSTO.25 | P94: SETEMBRO.25 | Q94: OUTUBRO.25 | R94: NOVEMBRO.25 | S94: DEZEMBRO.25
A95: HEPATITE B | B95: =0/7% -> 0 | C95: =0/18 -> 0 | D95: =0/24 -> 0 | E95: =0/39 -> 0 | F95: =0/26 -> 0 | G95: =0/16 -> 0 | H95: =0/30 -> 0 | I95: =0/28 -> 0 | J95: =0/19 -> 0 | K95: =1/25 -> 0.04 | L95: =0/32 -> 0 | M95: 0 | N95: 0 | O95: 0
A96: HEPATITE C | B96: =0/4 -> 0 | C96: =0/17 -> 0 | D96: =0/24 -> 0 | E96: =1/40 -> 0.025 | F96: =1/22 -> 0.045454545 | G96: =0/1 -> 0 | H96: =0/1 -> 0 | I96: =0/1 -> 0 | J96: =0/18 -> 0 | K96: =0/25 -> 0 | L96: =1/29 -> 0.034482759 | M96: 0.04 | N96: 0 | O96: 0
A97: HIV | B97: =0/7 -> 0 | C97: =0/21% -> 0 | D97: =2/27 -> 0.074074074 | E97: =2/71 -> 0.028169014 | F97: =1/34 -> 0.029411765 | G97: =1/24 -> 0.041666667 | H97: 0.00057142857 | I97: =0/29 -> 0 | J97: =1/34 -> 0.029411765 | K97: =4/28 -> 0.14285714 | L97: =0/33 -> 0 | M97: 0 | N97: 0 | O97: =3/36 -> 0.083333333
A98: SÍFILIS | B98: =1/7 -> 0.14285714 | C98: =2/17 -> 0.11764706 | D98: =0/26 -> 0 | E98: =2/75 -> 0.026666667 | F98: =0/30 -> 0 | G98: =1/16 -> 0.0625 | H98: =9/31 -> 0.29032258 | I98: =5/28 -> 0.17857143 | J98: =6/23 -> 0.26086957 | K98: =2/30 -> 0.066666667 | L98: =3/25 -> 0.12 | M98: 0.03 | N98: 0.08 | O98: =4/35 -> 0.11428571
A99: DENGUE | B99: =0/39 -> 0 | C99: =3/61 -> 0.049180328 | D99: =0/46 -> 0 | E99: =3/184 -> 0.016304348 | F99: =1/69 -> 0.014492754 | G99: =1/125 -> 0.008 | H99: =4/317 -> 0.012618297 | I99: =9/253 -> 0.035573123 | J99: =3/191 -> 0.015706806 | K99: =3/155 -> 0.019354839 | L99: =1/111 -> 0.009009009 | M99: 0 | N99: 0 | O99: =1/16 -> 0.0625
A100: COQUELUCHE | B100: 0 | C100: =3/68 -> 0.044117647 | D100: =22/133 -> 0.16541353 | E100: =5/34 -> 0.14705882 | F100: =1/33 -> 0.03030303 | G100: =1/33 -> 0.03030303 | H100: =1/33 -> 0.03030303 | P100: 7 | Q100: 8 | R100: 9 | S100: 10
A101: COVID-19 | B101: =0/32 -> 0 | C101: =37/219 -> 0.16894977 | D101: =6/107 -> 0.056074766 | E101: =33/251 -> 0.1314741 | F101: =37/230 -> 0.16086957 | G101: =43/250 -> 0.172 | H101: =40/203 -> 0.19704433 | I101: =98/310 -> 0.31612903 | J101: =37/340 -> 0.10882353 | K101: =3/196 -> 0.015306122 | L101: =1/235 -> 0.0042553191 | M101: 0.01 | N101: 0.02 | O101: =10/115 -> 0.086956522
C128: =15+11+1+12+12+12+8+7+10+6+6+13+6+4+6+9+12+4+7+14+8+8+13+7+16+13+16+5+3+2 -> 266
A145: Dia | B145: Não Reagente | C145: Reagente | D145: Total Geral
A146: 1 | B146: 8 | D146: =B146+C146 -> 8
A147: 2 | B147: 2 | D147: =B147+C147 -> 2
A148: 3 | B148: 2 | C148: 1 | D148: =B148+C148 -> 3
A149: 4 | B149: 3 | D149: =B149+C149 -> 3
A150: 5 | D150: =B150+C150 -> 0
A151: 6 | B151: 10 | D151: =B151+C151 -> 10
A152: 7 | B152: 3 | D152: =B152+C152 -> 3
...

Sheet NEP
A1: NÚCLEO DE EDUCAÇÃO PERMANENTE

Sheet APOIO
A1: SERVIÇOS DE APOIO
X20: 1 | Y20: 111
X21: 2 | Y21: 124.2
M22: Data | N22: Total (Kg) | X22: 3 | Y22: 142.8
M23: 45658 | N23: 65.8 | X23: 4 | Y23: 108
M24: 45659 | N24: 71 | X24: 5 | Y24: 71.3
M25: 45660 | N25: 40.4 | X25: 6 | Y25: 113
M26: 45661 | N26: 103.19 | X26: 7 | Y26: 127
M27: 45662 | N27: 88.6 | X27: 8 | Y27: 165
M28: 45663 | N28: 98 | X28: 9 | Y28: 73
M29: 45664 | N29: 92.5 | X29: 10 | Y29: 100
M30: 45665 | X30: 11 | Y30: 95
M31: 45666 | N31: 102.3 | X31: 12 | Y31: 85
M32: 45667 | N32: 101.8 | X32: 13 | Y32: 97.7
M33: 45668 | X33: 14 | Y33: 98.3
M34: 45669 | N34: 42.1 | X34: 15 | Y34: 112
M35: 45670 | N35: 118.5 | X35: 16 | Y35: 69.9
M36: 45671 | N36: 91.4 | X36: 17 | Y36: 78.2
M37: 45672 | N37: 71.4 | X37: 18 | Y37: 110.6
M38: 45673 | N38: 77.6 | X38: 19 | Y38: 109.7
M39: 45674 | N39: 62.9 | X39: 20 | Y39: 86.6
M40: 45675 | N40: 87.1 | X40: 21 | Y40: 70
M41: 45676 | N41: 61.03 | X41: 22 | Y41: 98
M42: 45677 | X42: 23 | Y42: 119.1
M43: 45678 | X43: 24 | Y43: 75
M44: 45679 | N44: 123.7 | X44: 25 | Y44: 98.6
M45: 45680 | N45: 58.7 | X45: 26 | Y45: 70
M46: 45681 | N46: 48.7 | X46: 27 | Y46: 141.2
M47: 45682 | X47: 28 | Y47: 62
M48: 45683 | N48: 44.2 | X48: 29 | Y48: 68.5
M49: 45684 | N49: 70.6 | X49: 30 | Y49: 127.5
M50: 45685 | N50: 73.1 | X50: 31 | Y50: 111.7
M51: 45686 | N51: 95.5 | Y51: =SUM(Y20:Y50) -> 3119.9
M52: 45687 | N52: 126.3
M53: 45688 | N53: 71.7
M54: TOTAL | N54: 87
N55: 87.8
N57: 55.9
N58: 114
N60: 113.5

Sheet PRODUTIVIDADE
A1: PRODUTIVIDADE DAS EQUIPES
M22: Data | N22: Total (Kg)
M23: 45566 | N23: 67.9
M24: 45567 | N24: 81.7
M25: 45568 | N25: 83.6
M26: 45569 | N26: 110.9
M27: 45570 | N27: 92.5
M28: 45571 | N28: 44.7
M29: 45572 | N29: 57.1
M30: 45573 | N30: 79.8
M31: 45574 | N31: 68
M32: 45575 | N32: 73.4
M33: 45576 | N33: 57.3
M34: 45577 | N34: 111.5
... M52: 45596 | N52: 91
M53: TOTAL

Sheet PESQUISA DE SATISFAÇÃO
A1: PESQUISA DE SATISFAÇÃO
A2: INDICADOR | B2: INDICADOR DE SATISFAÇÃO | D2: RESULTADO | E2: JULHO.24 | F2: AGOSTO.24 | G2: SETEMBRO.24 | H2: OUTUBRO.24 | I2: NOVEMBRO.24 | J2: DEZEMBRO.24 | K2: JANEIRO.25 | L2: FEVEREIRO.25 | M2: MARÇO.25 | N2: ABRIL.25 | O2: MAIO.25 | P2: JUNHO.25 | Q2: JULHO.25 | R2: AGOSTO.25 | S2: MÉDIA GERAL
A3: Atenção e interesse dos profissionais | C3: =S48 -> 0.944475 | D3: ÓTIMO | E3: 0.8988 | F3: 0.7868 | G3: 0.7167 | H3: 0.7484 | I3: 0.7877 | J3: 0.7561 | K3: 0.8447 | L3: 0.9481 | M3: 0.866 | N3: 0.8341 | O3: 0.7977 | P3: 0.8653 | Q3: 0.8257 | R3: 0.9459 | S3: =AVERAGE(K3:R3) -> 0.8659375
D4: BOM | E4: 0.0635 | F4: 0.1482 | G4: 0.1845 | H4: 0.1711 | I4: 0.1823 | J4: 0.1397 | K4: 0.0631 | L4: 0.0079 | M4: 0.0556 | N4: 0.1112 | O4: 0.1088 | P4: 0.1026 | Q4: 0.1384 | R4: 0.0407 | S4: =AVERAGE(K4:R4) -> 0.0785375
D5: REGULAR | E5: 0.0159 | F5: 0.0194 | G5: 0.0214 | H5: 0.0503 | I5: 0.0043 | J5: 0.0354 | K5: 0.0243 | L5: 0.0167 | M5: 0.019 | N5: 0.0167 | O5: 0.041 | P5: 0.0128 | Q5: 0.03 | R5: 0.0027 | S5: =AVERAGE(K5:R5) -> 0.0204
D6: RUIM | E6: 0.004 | F6: 0.0182 | G6: 0.0024 | H6: 0.0038 | I6: 0.0114 | J6: 0.0223 | K6: 0.0146 | L6: 0.0123 | M6: 0.0107 | N6: 0.0056 | O6: 0.0115 | P6: 0.0093 | Q6: 0 | R6: 0.0027 | S6: =AVERAGE(K6:R6) -> 0.0083375
D7: PÉSSIMO | E7: 0.0179 | F7: 0.0274 | G7: 0.075 | H7: 0.0264 | I7: 0.0142 | J7: 0.0466 | K7: 0.0534 | L7: 0.015 | M7: 0.0487 | N7: 0.0324 | O7: 0.041 | P7: 0.01 | Q7: 0.0059 | R7: 0.008 | S7: =AVERAGE(K7:R7) -> 0.0268
A8: Orientações recebidas sobre o tratamento,exames e procedimentos | C8: =S49 -> 0.9396375 | D8: ÓTIMO | E8: 0.869 | F8: 0.7822 | G8: 0.7119 | H8: 0.7522 | I8: 0.7835 | J8: 0.7542 | K8: 0.8155 | L8: 0.9313 | M8: 0.8446 | N8: 0.8128 | O8: 0.7695 | P8: 0.8589 | Q8: 0.8263 | R8: 0.9446 | S8: =AVERAGE(K8:R8) -> 0.8504375
D9: BOM | E9: 0.0972 | F9: 0.1494 | G9: 0.1893 | H9: 0.1686 | I9: 0.1809 | J9: 0.1546 | K9: 0.0825 | L9: 0.0264 | M9: 0.0586 | N9: 0.1251 | O9: 0.1357 | P9: 0.1026 | Q9: 0.1413 | R9: 0.0414 | S9: =AVERAGE(K9:R9) -> 0.0892
D10: REGULAR | E10: 0.0099 | F10: 0.0251 | G10: 0.0179 | H10: 0.0465 | I10: 0.01 | J10: 0.0261 | K10: 0.0437 | L10: 0.0185 | M10: 0.0327 | N10: 0.0259 | O10: 0.0474 | P10: 0.0207 | Q10: 0.0277 | R10: 0.0047 | S10: =AVERAGE(K10:R10) -> 0.0276625
D11: RUIM | E11: 0.0079 | F11: 0.0171 | G11: 0.0083 | H11: 0.005 | I11: 0.0085 | J11: 0.0186 | K11: 0.0097 | L11: 0.0035 | M11: 0.0145 | N11: 0.0065 | O11: 0.0205 | P11: 0.0078 | Q11: 0.0006 | R11: 0.0013 | S11: =AVERAGE(K11:R11) -> 0.00805
D12: PÉSSIMO | E12: 0.0159 | F12: 0.0262 | G12: 0.0726 | H12: 0.0277 | I12: 0.0171 | J12: 0.0466 | K12: 0.0485 | L12: 0.0202 | M12: 0.0495 | N12: 0.0297 | O12: 0.0269 | P12: 0.01 | Q12: 0.0041 | R12: 0.008 | S12: =AVERAGE(K12:R12) -> 0.0246125
A13: Tempo de espera para atendimento na recepção | C13: =S50 -> 0.9234625 | D13: ÓTIMO | E13: 0.8155 | F13: 0.7811 | G13: 0.7869 | H13: 0.8264 | I13: 0.8248 | J13: 0.7505 | K13: 0.767 | L13: 0.9199 | M13: 0.8104 | N13: 0.8054 | O13: 0.7029 | P13: 0.8403 | Q13: 0.8133 | R13: 0.9352 | S13: =AVERAGE(K13:R13) -> 0.8243
D14: BOM | E14: 0.1052 | F14: 0.1368 | G14: 0.1202 | H14: 0.122 | I14: 0.1467 | J14: 0.1359 | K14: 0.068 | L14: 0.0405 | M14: 0.099 | N14: 0.1075 | O14: 0.1613 | P14: 0.1155 | Q14: 0.1561 | R14: 0.0454 | S14: =AVERAGE(K14:R14) -> 0.0991625
D15: REGULAR | E15: 0.0397 | F15: 0.0296 | G15: 0.0131 | H15: 0.0189 | I15: 0.0057 | J15: 0.0298 | K15: 0.068 | L15: 0.0282 | M15: 0.0259 | N15: 0.0399 | O15: 0.0602 | P15: 0.0257 | Q15: 0.0259 | R15: 0.0087 | S15: =AVERAGE(K15:R15) -> 0.0353125
D16: RUIM | E16: 0.0119 | F16: 0.0125 | G16: 0.0048 | H16: 0.005 | I16: 0.0043 | J16: 0.0168 | K16: 0.0049 | L16: 0.0018 | M16: 0.0183 | N16: 0.0148 | O16: 0.0256 | P16: 0.0064 | Q16: 0.0018 | R16: 0.0013 | S16: =AVERAGE(K16:R16) -> 0.0093625
D17: PÉSSIMO | E17: 0.0278 | F17: 0.0399 | G17: 0.075 | H17: 0.0277 | I17: 0.0185 | J17: 0.067 | K17: 0.0922 | L17: 0.0097 | M17: 0.0465 | N17: 0.0324 | O17: 0.0499 | P17: 0.0121 | Q17: 0.0029 | R17: 0.0093 | S17: =AVERAGE(K17:R17) -> 0.031875
A18: Tempo de espera para atendimento médico | C18: =S51 -> 0.8326 | D18: ÓTIMO | E18: 0.7163 | F18: 0.626 | G18: 0.65 | H18: 0.7132 | I18: 0.7621 | J18: 0.6704 | K18: 0.7524 | L18: 0.6083 | M18: 0.6405 | N18: 0.7285 | O18: 0.644 | P18: 0.819 | Q18: 0.7915 | R18: 0.8672 | S18: =AVERAGE(K18:R18) -> 0.731425
D19: BOM | E19: 0.1052 | F19: 0.1277 | G19: 0.1238 | H19: 0.1421 | I19: 0.1681 | J19: 0.1378 | K19: 0.0485 | L19: 0.0933 | M19: 0.1089 | N19: 0.1288 | O19: 0.114 | P19: 0.1133 | Q19: 0.1525 | R19: 0.0501 | S19: =AVERAGE(K19:R19) -> 0.101175
D20: REGULAR | E20: 0.0754 | F20: 0.1072 | G20: 0.0952 | H20: 0.0704 | I20: 0.0299 | J20: 0.1043 | K20: 0.0631 | L20: 0.1356 | M20: 0.0739 | N20: 0.0667 | O20: 0.0986 | P20: 0.0342 | Q20: 0.0342 | R20: 0.0167 | S20: =AVERAGE(K20:R20) -> 0.065375
D21: RUIM | E21: 0.0397 | F21: 0.0445 | G21: 0.0321 | H21: 0.0327 | I21: 0.0071 | J21: 0.0168 | K21: 0.0534 | L21: 0.0405 | M21: 0.0327 | N21: 0.0222 | O21: 0.0435 | P21: 0.0135 | Q21: 0.0135 | R21: 0.0134 | S21: =AVERAGE(K21:R21) -> 0.0290875
D22: PÉSSIMO | E22: 0.0635 | F22: 0.0946 | G22: 0.0988 | H22: 0.0415 | I22: 0.0328 | J22: 0.0708 | K22: 0.0825 | L22: 0.1224 | M22: 0.1439 | N22: 0.0538 | O22: 0.0999 | P22: 0.02 | Q22: 0.0082 | R22: 0.0527 | S22: =AVERAGE(K22:R22) -> 0.072925
A23: Instalações físicas | C23: =S52 -> 0.8872125 | D23: ÓTIMO | E23: 0.6984 | F23: 0.6123 | G23: 0.5012 | H23: 0.5849 | I23: 0.7308 | J23: 0.689 | K23: 0.7767 | L23: 0.7852 | M23: 0.7342 | N23: 0.7396 | O23: 0.7017 | P23: 0.8011 | Q23: 0.765 | R23: 0.8511 | S23: =AVERAGE(K23:R23) -> 0.769325
D24: BOM | E24: 0.1845 | F24: 0.2109 | G24: 0.3333 | H24: 0.3044 | I24: 0.2151 | J24: 0.162 | K24: 0.1165 | L24: 0.0352 | M24: 0.1386 | N24: 0.1538 | O24: 0.1485 | P24: 0.1361 | Q24: 0.1637 | R24: 0.0507 | S24: =AVERAGE(K24:R24) -> 0.1178875
D25: REGULAR | E25: 0.0774 | F25: 0.0992 | G25: 0.0738 | H25: 0.0616 | I25: 0.0285 | J25: 0.0931 | K25: 0.0583 | L25: 0.1083 | M25: 0.0724 | N25: 0.0658 | O25: 0.0832 | P25: 0.0314 | Q25: 0.0442 | R25: 0.014 | S25: =AVERAGE(K25:R25) -> 0.0597
D26: RUIM | E26: 0.0179 | F26: 0.0365 | G26: 0.0167 | H26: 0.0063 | I26: 0.0085 | J26: 0.0074 | K26: 0.0146 | L26: 0.0396 | M26: 0.016 | N26: 0.0093 | O26: 0.0218 | P26: 0.0178 | Q26: 0.0112 | R26: 0.0294 | S26: =AVERAGE(K26:R26) -> 0.0199625
D27: PÉSSIMO | E27: 0.0218 | F27: 0.041 | G27: 0.075 | H27: 0.0428 | I27: 0.0171 | J27: 0.0484 | K27: 0.034 | L27: 0.0317 | M27: 0.0388 | N27: 0.0315 | O27: 0.0448 | P27: 0.0135 | Q27: 0.0159 | R27: 0.0547 | S27: =AVERAGE(K27:R27) -> 0.0331125
A28: Você indicaria este serviço a um familiar ou amigo | C28: =S53 -> 0.905175 | D28: ÓTIMO | E28: 0.8294 | F28: 0.7047 | G28: 0.6905 | H28: 0.766 | I28: 0.7892 | J28: 0.7467 | K28: 0.7718 | L28: 0.8856 | M28: 0.7807 | N28: 0.8054 | O28: 0.7081 | P28: 0.8354 | Q28: 0.8051 | R28: 0.8772 | S28: =AVERAGE(K28:R28) -> 0.8086625
D29: BOM | E29: 0.0952 | F29: 0.1756 | G29: 0.1798 | H29: 0.1447 | I29: 0.1638 | J29: 0.1471 | K29: 0.068 | L29: 0.0176 | M29: 0.0982 | N29: 0.1196 | O29: 0.1255 | P29: 0.1276 | Q29: 0.1508 | R29: 0.0648 | S29: =AVERAGE(K29:R29) -> 0.0965125
D30: REGULAR | E30: 0.0298 | F30: 0.0468 | G30: 0.0369 | H30: 0.0277 | I30: 0.0142 | J30: 0.0354 | K30: 0.0777 | L30: 0.0317 | M30: 0.032 | N30: 0.025 | O30: 0.0679 | P30: 0.015 | Q30: 0.0365 | R30: 0.034 | S30: =AVERAGE(K30:R30) -> 0.039975
D31: RUIM | E31: 0.006 | F31: 0.016 | G31: 0.0095 | H31: 0.005 | I31: 0.0114 | J31: 0.0168 | K31: 0.0146 | L31: 0.0035 | M31: 0.019 | N31: 0.0093 | O31: 0.0384 | P31: 0.0078 | Q31: 0.0029 | R31: 0.0107 | S31: =AVERAGE(K31:R31) -> 0.013275
D32: PÉSSIMO | E32: 0.0397 | F32: 0.057 | G32: 0.0833 | H32: 0.0566 | I32: 0.0214 | J32: 0.054 | K32: 0.068 | L32: 0.0616 | M32: 0.0701 | N32: 0.0408 | O32: 0.0602 | P32: 0.0143 | Q32: 0.0047 | R32: 0.0134 | S32: =AVERAGE(K32:R32) -> 0.0416375
A33: Você voltaria a utilizar este serviço | C33: =S54 -> 0.9269375 | D33: ÓTIMO | E33: 0.8333 | F33: 0.6978 | G33: 0.7012 | H33: 0.7925 | I33: 0.8006 | J33: 0.7672 | K33: 0.7864 | L33: 0.9313 | M33: 0.8599 | N33: 0.8313 | O33: 0.7426 | P33: 0.8646 | Q33: 0.8186 | R33: 0.8832 | S33: =AVERAGE(K33:R33) -> 0.8397375
D34: BOM | E34: 0.0952 | F34: 0.1847 | G34: 0.1833 | H34: 0.1245 | I34: 0.1567 | J34: 0.1341 | K34: 0.0534 | L34: 0.0194 | M34: 0.051 | N34: 0.1057 | O34: 0.1332 | P34: 0.1041 | Q34: 0.1413 | R34: 0.0895 | S34: =AVERAGE(K34:R34) -> 0.0872
D35: REGULAR | E35: 0.0258 | F35: 0.0456 | G35: 0.031 | H35: 0.0302 | I35: 0.0171 | J35: 0.0298 | K35: 0.0825 | L35: 0.007 | M35: 0.0259 | N35: 0.0297 | O35: 0.0423 | P35: 0.0128 | Q35: 0.0318 | R35: 0.0154 | S35: =AVERAGE(K35:R35) -> 0.030925
D36: RUIM | E36: 0.0099 | F36: 0.0217 | G36: 0.006 | H36: 0.0038 | I36: 0.0085 | J36: 0.0186 | K36: 0.0049 | L36: 0.0062 | M36: 0.016 | N36: 0.0056 | O36: 0.0384 | P36: 0.0093 | Q36: 0.0029 | R36: 0.002 | S36: =AVERAGE(K36:R36) -> 0.0106625
D37: PÉSSIMO | E37: 0.0357 | F37: 0.0502 | G37: 0.0786 | H37: 0.0491 | I37: 0.0171 | J37: 0.0503 | K37: 0.0728 | L37: 0.0361 | M37: 0.0472 | N37: 0.0278 | O37: 0.0435 | P37: 0.0093 | Q37: 0.0053 | R37: 0.01 | S37: =AVERAGE(K37:R37) -> 0.0315
A38: Tempo de espera para acolhimento (triagem) | C38: =S55 -> 0.9353375 | D38: ÓTIMO | E38: 0.8413 | F38: 0.7777 | G38: 0.7524 | H38: 0.8365 | I38: 0.812 | J38: 0.7784 | K38: 0.801 | L38: 0.9375 | M38: 0.8606 | N38: 0.8332 | O38: 0.7375 | P38: 0.8503 | Q38: 0.8157 | R38: 0.9266 | S38: =AVERAGE(K38:R38) -> 0.8453
D39: BOM | E39: 0.1032 | F39: 0.13 | G39: 0.1262 | H39: 0.1094 | I39: 0.1553 | J39: 0.1415 | K39: 0.0583 | L39: 0.029 | M39: 0.0823 | N39: 0.1047 | O39: 0.1293 | P39: 0.1155 | Q39: 0.1478 | R39: 0.0534 | S39: =AVERAGE(K39:R39) -> 0.0900375
D40: REGULAR | E40: 0.0258 | F40: 0.0342 | G40: 0.0369 | H40: 0.0214 | I40: 0.0043 | J40: 0.013 | K40: 0.0534 | L40: 0.0088 | M40: 0.0183 | N40: 0.0287 | O40: 0.0627 | P40: 0.0178 | Q40: 0.03 | R40: 0.0027 | S40: =AVERAGE(K40:R40) -> 0.0278
...

Sheet MAPA DE CALOR 2024
A1: MAPA DE CALOR - DEMANDA DE PRONTO ATENDIMENTO
A2: Julho de 2024
A3: HORA | B3: Segunda | C3: Terça | D3: Quarta | E3: Quinta | F3: Sexta | G3: Sábado | H3: Domingo
A4: 00:00 às 00:59 | B4: 4 | C4: 6.2 | D4: 5.4 | E4: 5.75 | F4: 6.25 | G4: 5.25 | H4: 4
A5: 01:00 às 01:59 | B5: 2.2 | C5: 2.2 | D5: 2.2 | E5: 4 | F5: 3.25 | G5: 4.25 | H5: 4
A6: 02:00 às 02:59 | B6: 2.2 | C6: 1.6 | D6: 1.8 | E6: 3.25 | F6: 3.5 | G6: 3.5 | H6: 2.25
A7: 03:00 às 03:59 | B7: 2.8 | C7: 2 | D7: 2.2 | E7: 3 | F7: 2.5 | G7: 3.75 | H7: 1.75
A8: 04:00 às 04:59 | B8: 2.8 | C8: 3.2 | D8: 2.2 | E8: 2.75 | F8: 2.5 | G8: 2.75 | H8: 3
A9: 05:00 às 05:59 | B9: 7.6 | C9: 4.6 | D9: 8 | E9: 5 | F9: 6.75 | G9: 3.75 | H9: 3.25
A10: 06:00 às 06:59 | B10: 16.8 | C10: 12.8 | D10: 12.2 | E10: 12.25 | F10: 11.75 | G10: 7 | H10: 7
A11: 07:00 às 07:59 | B11: 18 | C11: 16 | D11: 16 | E11: 14.25 | F11: 19.5 | G11: 13 | H11: 5.25
A12: 08:00 às 08:59 | B12: 20.8 | C12: 21.4 | D12: 18.8 | E12: 21.5 | F12: 15.5 | G12: 9.5 | H12: 7.5
A13: 09:00 às 09:59 | B13: 23.8 | C13: 18.2 | D13: 17.2 | E13: 21.5 | F13: 20 | G13: 10.25 | H13: 12.25
A14: 10:00 às 10:59 | B14: 20.2 | C14: 19.6 | D14: 22.6 | E14: 16 | F14: 19.25 | G14: 15.25 | H14: 12.25
A15: 11:00 às 11:59 | B15: 24.6 | C15: 13.8 | D15: 14.2 | E15: 18.75 | F15: 17.75 | G15: 13 | H15: 13
... A28: TOTAL | B28: 339.2 | C28: 276.8 | D28: 292.8 | E28: 298.25 | F28: 284.5 | G28: 198 | H28: 204.25
A32: Agosto de 2024
A33: HORA | B33: Segunda | C33: Terça | D33: Quarta | E33: Quinta | F33: Sexta | G33: Sábado | H33: Domingo
A34: 00:00 às 00:59 | B34: 5.5 | C34: 8.25 | D34: 4.25 | E34: 7.8 | F34: 9 | G34: 7.6 | H34: 6
A35: 01:00 às 01:59 | B35: 2.25 | C35: 4.25 | D35: 2.75 | E35: 5 | F35: 5 | G35: 4 | H35: 3
A36: 02:00 às 02:59 | B36: 3 | C36: 2 | D36: 2.5 | E36: 3.8 | F36: 3.6 | G36: 5.2 | H36: 4
A37: 03:00 às 03:59 | B37: 4.75 | C37: 6.5 | D37: 3.5 | E37: 2 | F37: 2 | G37: 3.4 | H37: 2.5
A38: 04:00 às 04:59 | B38: 4 | C38: 2.75 | D38: 4 | E38: 4.4 | F38: 3 | G38: 3 | H38: 2.75
A39: 05:00 às 05:59 | B39: 7.5 | C39: 8.5 | D39: 9.25 | E39: 12 | F39: 12 | G39: 8 | H39: 3.25
A40: 06:00 às 06:59 | B40: 20 | C40: 15 | D40: 11.75 | E40: 16.6 | F40: 14.2 | G40: 7.8 | H40: 4.75
A41: 07:00 às 07:59 | B41: 23 | C41: 18.5 | D41: 28 | E41: 23.2 | F41: 22.4 | G41: 13 | H41: 8.25
A42: 08:00 às 08:59 | B42: 31.5 | C42: 27.25 | D42: 25.5 | E42: 24.4 | F42: 23.8 | G42: 15.2 | H42: 8
A43: 09:00 às 09:59 | B43: 31.25 | C43: 24.5 | D43: 29.5 | E43: 24.6 | F43: 20.2 | G43: 19 | H43: 13.5
A44: 10:00 às 10:59 | B44: 24.25 | C44: 25.25 | D44: 22.75 | E44: 22 | F44: 21.2 | G44: 20.8 | H44: 14
A45: 11:00 às 11:59 | B45: 22.25 | C45: 20.75 | D45: 21.75 | E45: 18.6 | F45: 17.4 | G45: 17.2 | H45: 11.75
... A58: TOTAL | B58: 432.75 | C58: 379.5 | D58: 372.25 | E58: 365.8 | F58: 339.4 | G58: 272.6 | H58: 234.75
A62: Setembro de 2024
A63: HORA | B63: Segunda | C63: Terça | D63: Quarta | E63: Quinta | F63: Sexta | G63: Sábado | H63: Domingo
A64: 00:00 às 00:59 | B64: 7.4 | C64: 8.25 | D64: 8 | E64: 7.75 | F64: 5 | G64: 6.5 | H64: 4.6
A65: 01:00 às 01:59 | B65: 4.2 | C65: 5.5 | D65: 4.25 | E65: 7 | F65: 7.75 | G65: 5 | H65: 3.8
A66: 02:00 às 02:59 | B66: 3.6 | C66: 3.5 | D66: 4.75 | E66: 3.25 | F66: 5 | G66: 3.25 | H66: 4.2
A67: 03:00 às 03:59 | B67: 2.8 | C67: 5.75 | D67: 3.5 | E67: 4.25 | F67: 4.25 | G67: 6.25 | H67: 3
A68: 04:00 às 04:59 | B68: 4.4 | C68: 5.75 | D68: 3.75 | E68: 6.25 | F68: 4 | G68: 4.25 | H68: 3
A69: 05:00 às 05:59 | B69: 9.6 | C69: 12.75 | D69: 11.75 | E69: 9.75 | F69: 14 | G69: 6.75 | H69: 3.6
A70: 06:00 às 06:59 | B70: 19.8 | C70: 19.75 | D70: 17.5 | E70: 18.25 | F70: 21 | G70: 9.25 | H70: 5.2
...

Sheet MAPA DE CALOR 2025
A1: Mapa de Calor - Demanda de Pronto Atendimento
A2: Janeiro de 2025
A3: HORA | B3: Segunda | C3: Terça | D3: Quarta | E3: Quinta | F3: Sexta | G3: Sábado | H3: Domingo
A4: 00:00 às 00:59 | B4: 9.5 | C4: 8.25 | D4: 5.4 | E4: 4.4 | F4: 8.6 | G4: 8.75 | H4: 6.5
A5: 01:00 às 01:59 | B5: 4.25 | C5: 4.75 | D5: 6 | E5: 4.8 | F5: 5 | G5: 3.25 | H5: 5.5
A6: 02:00 às 02:59 | B6: 2 | C6: 3 | D6: 4.2 | E6: 4 | F6: 2.4 | G6: 5.25 | H6: 4
A7: 03:00 às 03:59 | B7: 0.5 | C7: 1.75 | D7: 4 | E7: 4.2 | F7: 1.6 | G7: 2.5 | H7: 1.75
A8: 04:00 às 04:59 | B8: 2.75 | C8: 4.75 | D8: 4.2 | E8: 3 | F8: 3.4 | G8: 3.25 | H8: 3.25
A9: 05:00 às 05:59 | B9: 5 | C9: 9 | D9: 3.6 | E9: 6.6 | F9: 7.2 | G9: 8 | H9: 4.5
A10: 06:00 às 06:59 | B10: 16 | C10: 15.5 | D10: 14.8 | E10: 14.4 | F10: 15.4 | G10: 10.25 | H10: 8.5
A11: 07:00 às 07:59 | B11: 24 | C11: 22.25 | D11: 20.2 | E11: 23.8 | F11: 17.2 | G11: 13.5 | H11: 10.5
A12: 08:00 às 08:59 | B12: 30.5 | C12: 28 | D12: 19 | E12: 22.2 | F12: 24 | G12: 15.25 | H12: 10
A13: 09:00 às 09:59 | B13: 29 | C13: 27.5 | D13: 20.8 | E13: 22.8 | F13: 19.8 | G13: 18.5 | H13: 13.75
A14: 10:00 às 10:59 | B14: 31.5 | C14: 23 | D14: 20.4 | E14: 22.4 | F14: 23.2 | G14: 22 | H14: 16.75
A15: 11:00 às 11:59 | B15: 25 | C15: 25.5 | D15: 19.6 | E15: 26 | F15: 25.6 | G15: 20 | H15: 12.75
... A28: TOTAL | B28: 414 | C28: 374.75 | D28: 331.4 | E28: 367.6 | F28: 345.4 | G28: 301.5 | H28: 258.5
A32: Fevereiro de 2025
A33: HORA | B33: Segunda | C33: Terça | D33: Quarta | E33: Quinta | F33: Sexta | G33: Sábado | H33: Domingo
A34: 00:00 às 00:59 | B34: 5.75 | C34: 8.5 | D34: 5.75 | E34: 8 | F34: 6.8 | G34: 6.4 | H34: 5
A35: 01:00 às 01:59 | B35: 4.75 | C35: 4.5 | D35: 5 | E35: 3.75 | F35: 5.8 | G35: 5.2 | H35: 3.25
A36: 02:00 às 02:59 | B36: 2.75 | C36: 2.5 | D36: 3.25 | E36: 2.75 | F36: 3.2 | G36: 3.2 | H36: 4.5
A37: 03:00 às 03:59 | B37: 3 | C37: 3 | D37: 2 | E37: 2.75 | F37: 2.4 | G37: 4.4 | H37: 3.75
A38: 04:00 às 04:59 | B38: 3.5 | C38: 5 | D38: 4 | E38: 3.5 | F38: 3.8 | G38: 1.8 | H38: 3.25
A39: 05:00 às 05:59 | B39: 9.5 | C39: 8.5 | D39: 8 | E39: 9.5 | F39: 8.2 | G39: 3.8 | H39: 4.25
A40: 06:00 às 06:59 | B40: 19.5 | C40: 21 | D40: 14.5 | E40: 14 | F40: 17.2 | G40: 9.8 | H40: 6
A41: 07:00 às 07:59 | B41: 21.25 | C41: 23.5 | D41: 18.75 | E41: 16.5 | F41: 19.2 | G41: 13 | H41: 9.75
A42: 08:00 às 08:59 | B42: 33.5 | C42: 29.25 | D42: 22 | E42: 24.25 | F42: 24.8 | G42: 12 | H42: 10.25
A43: 09:00 às 09:59 | B43: 26.5 | C43: 24.25 | D43: 21.5 | E43: 24 | F43: 18.8 | G43: 14.4 | H43: 15.75
A44: 10:00 às 10:59 | B44: 25 | C44: 22.25 | D44: 18 | E44: 19.25 | F44: 18.6 | G44: 14.8 | H44: 16.75
A45: 11:00 às 11:59 | B45: 23 | C45: 19 | D45: 18.25 | E45: 16 | F45: 19 | G45: 17 | H45: 15.5
... A58: TOTAL | B58: 432.75 | C58: 379.5 | D58: 372.25 | E58: 365.8 | F58: 339.4 | G58: 272.6 | H58: 234.75
A62: Março de 2025
A63: HORA | B63: Segunda | C63: Terça | D63: Quarta | E63: Quinta | F63: Sexta | G63: Sábado | H63: Domingo
A64: 00:00 às 00:59 | B64: 7.2 | C64: 7.75 | D64: 5.25 | E64: 8.5 | F64: 5 | G64: 6.6 | H64: 7.2
A65: 01:00 às 01:59 | B65: 4.8 | C65: 6 | D65: 3.75 | E65: 5.5 | F65: 2.5 | G65: 5.4 | H65: 4.8
A66: 02:00 às 02:59 | B66: 2.2 | C66: 4 | D66: 4 | E66: 2.5 | F66: 1.5 | G66: 2.6 | H66: 2.2
A67: 03:00 às 03:59 | B67: 2.8 | C67: 2.75 | D67: 2.5 | E67: 2 | F67: 3 | G67: 3.6 | H67: 3.6
A68: 04:00 às 04:59 | B68: 5.2 | C68: 4.25 | D68: 3.75 | E68: 2.5 | F68: 3.25 | G68: 3.2 | H68: 4.2
A69: 05:00 às 05:59 | B69: 8.6 | C69: 6.5 | D69: 8 | E69: 9.25 | F69: 7.25 | G69: 9.2 | H69: 4.8
A70: 06:00 às 06:59 | B70: 20.8 | C70: 17 | D70: 20.5 | E70: 15 | F70: 14 | G70: 11.6 | H70: 5
...
